Workbook

Sheet DCF Valuation
B3: DCF Valuation of Maruti Suzuki
C4: Historical Growth | F4: Explicit Growth
B5: Particulars | C5: 2023 | D5: =C5+1 -> 2024 | E5: =D5+1 -> 2025 | F5: 2026 | G5: 2027 | H5: 2028 | I5: 2029 | J5: 2030
B6: Sales | C6: ='Raw Data'!J5 -> 60580 | D6: ='Raw Data'!K5 -> 61896 | E6: ='Raw Data'!L5 -> 63121 | F6: =E6*(1+F7) -> 66277.05 | G6: =F6*(1+G7) -> 69590.903 | H6: =G6*(1+H7) -> 73070.448 | I6: =H6*(1+I7) -> 76723.97 | J6: =I6*(1+J7) -> 80560.169
B7: Sales % Growth | D7: =(D6-C6)/C6 -> 0.021723341 | E7: =(E6-D6)/D6 -> 0.019791263 | F7: 0.05 | G7: 0.05 | H7: 0.05 | I7: 0.05 | J7: 0.05
B8: EBIT Margin | C8: ='Raw Data'!J15 -> 0.21475735 | D8: ='Raw Data'!K15 -> 0.21718689 | E8: ='Raw Data'!L15 -> 0.21368483 | F8: 0.21 | G8: 0.21 | H8: 0.21 | I8: 0.21 | J8: 0.21
B9: EBIT | C9: =C6*C8 -> 13010 | D9: =D6*D8 -> 13443 | E9: =E6*E8 -> 13488 | F9: =F6*F8 -> 13918.181 | G9: =G6*G8 -> 14614.09 | H9: =H6*H8 -> 15344.794 | I9: =I6*I8 -> 16112.034 | J9: =J6*J8 -> 16917.635
B10: Less: Actual Tax | C10: =Forecasting!J8 -> 3201 | D10: =Forecasting!K8 -> 3644 | E10: =Forecasting!L8 -> 3744 | F10: =F9*Forecasting!$C$13 -> 3763.476 | G10: =G9*Forecasting!$C$13 -> 3951.6498 | H10: =H9*Forecasting!$C$13 -> 4149.2323 | I10: =I9*Forecasting!$C$13 -> 4356.6939 | J10: =J9*Forecasting!$C$13 -> 4574.5286
B11: NOPAT | C11: =C9-C10 -> 9809 | D11: =D9-D10 -> 9799 | E11: =E9-E10 -> 9744 | F11: =F9-F10 -> 10154.704 | G11: =G9-G10 -> 10662.44 | H11: =H9-H10 -> 11195.562 | I11: =I9-I10 -> 11755.34 | J11: =J9-J10 -> 12343.107
B12: Less:Capex | C12: =-Forecasting!C77 -> -1137 | D12: =-Forecasting!D77 -> -1216 | E12: =-Forecasting!E77 -> -1355 | F12: =-Forecasting!F77 -> -1325.541 | G12: =-Forecasting!G77 -> -1391.8181 | H12: =-Forecasting!H77 -> -1461.409 | I12: =-Forecasting!I77 -> -1534.4794 | J12: =-Forecasting!J77 -> -1611.2034
B13: Add: Change in Working Cap | D13: =-Forecasting!D53 -> 3737.8082 | E13: =-Forecasting!E53 -> 407.86575 | F13: =-Forecasting!F53 -> 2429.7262 | G13: =-Forecasting!G53 -> 735.40288 | H13: =-Forecasting!H53 -> 772.17303 | I13: =-Forecasting!I53 -> 810.78168 | J13: =-Forecasting!J53 -> 851.32076
B14: Add: Depreciation | C14: ='Raw Data'!J20 -> 1137 | D14: ='Raw Data'!K20 -> 1216 | E14: ='Raw Data'!L20 -> 1355 | F14: =2%*F6 -> 1325.541 | G14: =2%*G6 -> 1391.8181 | H14: =2%*H6 -> 1461.409 | I14: =2%*I6 -> 1534.4794 | J14: =2%*J6 -> 1611.2034
B15: Free Casf Flow to Firm | C15: =SUM(C11:C14) -> 9809 | D15: =SUM(D11:D14) -> 13536.808 | E15: =SUM(E11:E14) -> 10151.866 | F15: =SUM(F11:F14) -> 12584.431 | G15: =SUM(G11:G14) -> 11397.843 | H15: =SUM(H11:H14) -> 11967.735 | I15: =SUM(I11:I14) -> 12566.121 | J15: =SUM(J11:J14) -> 13194.428
B16: Cost of Capital | C16: ='WACC '!C17 -> 0.082105019
B17: Discounting Period (Years) | F17: 1 | G17: =F17+1 -> 2 | H17: =G17+1 -> 3 | I17: =H17+1 -> 4 | J17: =I17+1 -> 5
B18: Present Value Factor | F18: =1/(1+$C$16)^F17 -> 0.92412472 | G18: =1/(1+$C$16)^G17 -> 0.8540065 | H18: =1/(1+$C$16)^H17 -> 0.78920852 | I18: =1/(1+$C$16)^I17 -> 0.7293271 | J18: =1/(1+$C$16)^J17 -> 0.67398921
B19: Present Value of FCFF | F19: =F15*F18 -> 11629.583 | G19: =G15*G18 -> 9733.8317 | H19: =H15*H18 -> 9445.0382 | I19: =I15*I18 -> 9164.813 | J19: =J15*J18 -> 8892.9018
B21: DCF Valuation of Maruti Suzuki India Ltd
B23: Terminal Value of FCFF | C23: =J15 -> 13194.428
B24: Terminal Year Growth Rate | C24: 0.06
B25: Value of Terminal CF at 5th Yr | C25: =(C23*(1+C24))/(C16-C24) -> 632711.2
B26: PV of Terminal CF | C26: =C25*J18 -> 426440.52
B27: Pv of Forecasted CF | C27: =SUM(F19:J19) -> 48866.168
B28: Firm Value/Enterprise Value | C28: =SUM(C26:C27) -> 475306.69
B29: Less:Value of Debt | C29: =-1648 -> -1648
B30: Add: Cash & Non operating Investment | C30: =7554+242+4679 -> 12475
B31: Less: Value of Stock options/ Warrants | C31: =-55.2 -> -55.2
B32: Equity Value | C32: =SUM(C28:C31) -> 486078.49
B33: No Eq Shares | C33: =235 -> 235
B34: Equity Value Per Share | C34: =C32/C33 -> 2068.4191 | D34: Intrinsic Value
B35: Current Market Price | C35: =2545 -> 2545 | D35: Market Price on 03 Oct 2025
B36: Verdict | C36: Undervalue

Sheet WACC 
B3: WACC Calculation-Maruti Suzuki India Ltd.
B5: Particulars | C5: Values | D5: Source
B6: Risk Free Rate | C6: 0.065 | D6: 10Y Govt Bond Yield-investing.com
B7: Equity Risk Premium | C7: =C23-C6 -> 0.034999705 | D7: Rm-Rf-3Y Period
B8: Beta (3Y-Daily) | C8: =Sheet6!L5 -> 0.49106627 | D8: Regression based Beta
B9: Cost of Equity | C9: =C6+(C7*C8) -> 0.082187174 | D9: Calculated using CAPM Approach
B10: Corporate Credit Rating | C10: AAA | D10: Latest Crisil Rating Report
B11: Corporate Default Spread | C11: =C30 -> 0.01 | D11: Excess returns over riskfree rate by Golden PI
B12: Cost of Debt (Pre-Tax) | C12: =C28 -> 0.075 | D12: Risk Free Rate + Default Spread
B13: Marginal Tax Rate | C13: =27.04% -> 0.2704 | D13: Notified tax rate in Finanace bill, 2025
B14: Cost of Debt (Post-Tax) | C14: =C12*(1-C13) -> 0.05472 | D14: Post Tax Cost of Debt
B15: Debt to Equity Ratio | C15: =0.3% -> 0.003 | D15: Latest Financial
B16: Debt to Capital Ratio | C16: =C15/1.003 -> 0.0029910269 | D16: Latest Financial
B17: Weighted Average Cost of Capital | C17: =(C14*C16)+(C9*(1-C16)) -> 0.082105019
B20: Rough Work
B21: Nifty- 1-Apr-2022 | C21: 17670.45
B22: Nifty-28 Mar 20225 | C22: 23519.35
B23: CAGR Return (Rm) | C23: =_xlfn.RRI(3,C21,C22) -> 0.099999705
B24: Rf | C24: 0.065
B25: ERP (Rm-Rf) | C25: =C23-C24 -> 0.034999705
B27: Golden Pi
B28: AAA Rated Bonds Median | C28: 0.075
B29: 10Yr Bond Govt Rate | C29: 0.065
B30: Corporate Default Spread | C30: =C28-C29 -> 0.01

Sheet Sheet6
B1: Beta Drifting
B2: Date | C2: HUL | D2: Return | F2: Date | G2: Nifty 50 | H2: Return
B3: 44652 | C3: 2078.15 | F3: 44652 | G3: 17670.45
B4: 44655 | C4: 2128.45 | D4: =(C4-C3)/C3 -> 0.02420422 | F4: 44655 | G4: 18053.4 | H4: =(G4-G3)/G3 -> 0.021671774
B5: 44656 | C5: 2139.8 | D5: =(C5-C4)/C4 -> 0.005332519 | F5: 44656 | G5: 17957.4 | H5: =(G5-G4)/G4 -> -0.0053175579 | K5: Beta | L5: =SLOPE(D4:D746,H4:H746) -> 0.49106627
B6: 44657 | C6: 2142.05 | D6: =(C6-C5)/C5 -> 0.0010515001 | F6: 44657 | G6: 17807.65 | H6: =(G6-G5)/G5 -> -0.0083391805
B7: 44658 | C7: 2164.8 | D7: =(C7-C6)/C6 -> 0.010620667 | F7: 44658 | G7: 17639.55 | H7: =(G7-G6)/G6 -> -0.0094397632
B8: 44659 | C8: 2183.05 | D8: =(C8-C7)/C7 -> 0.00843034 | F8: 44659 | G8: 17784.35 | H8: =(G8-G7)/G7 -> 0.0082088262
B9: 44662 | C9: 2163.05 | D9: =(C9-C8)/C8 -> -0.0091614942 | F9: 44662 | G9: 17674.95 | H9: =(G9-G8)/G8 -> -0.0061514759
B10: 44663 | C10: 2132.25 | D10: =(C10-C9)/C9 -> -0.014239153 | F10: 44663 | G10: 17530.3 | H10: =(G10-G9)/G9 -> -0.0081838987
B11: 44664 | C11: 2152.15 | D11: =(C11-C10)/C10 -> 0.0093328643 | F11: 44664 | G11: 17475.65 | H11: =(G11-G10)/G10 -> -0.0031174595
B12: 44669 | C12: 2177.65 | D12: =(C12-C11)/C11 -> 0.011848616 | F12: 44669 | G12: 17173.65 | H12: =(G12-G11)/G11 -> -0.017281188
B13: 44670 | C13: 2113.05 | D13: =(C13-C12)/C12 -> -0.029665006 | F13: 44670 | G13: 16958.65 | H13: =(G13-G12)/G12 -> -0.012519179
B14: 44671 | C14: 2164.95 | D14: =(C14-C13)/C13 -> 0.024561653 | F14: 44671 | G14: 17136.55 | H14: =(G14-G13)/G13 -> 0.010490222
B15: 44672 | C15: 2197.95 | D15: =(C15-C14)/C14 -> 0.015242846 | F15: 44672 | G15: 17392.6 | H15: =(G15-G14)/G14 -> 0.014941747
B16: 44673 | C16: 2126.95 | D16: =(C16-C15)/C15 -> -0.032302828 | F16: 44673 | G16: 17171.95 | H16: =(G16-G15)/G15 -> -0.01268643
B17: 44676 | C17: 2100.75 | D17: =(C17-C16)/C16 -> -0.012318108 | F17: 44676 | G17: 16953.95 | H17: =(G17-G16)/G16 -> -0.012695122
... B746: 45744 | C746: 2258.85 | D746: =(C746-C745)/C745 -> 0.0063261533 | F746: 45744 | G746: 23519.35 | H746: =(G746-G745)/G745 -> -0.0030773209

Sheet Forecasting
B3: Forecasting
B5: Particulars | C5: ='Raw Data'!C4 -> 42430 | D5: ='Raw Data'!D4 -> 42795 | E5: ='Raw Data'!E4 -> 43160 | F5: ='Raw Data'!F4 -> 43525 | G5: ='Raw Data'!G4 -> 43891 | H5: ='Raw Data'!H4 -> 44256 | I5: ='Raw Data'!I4 -> 44621 | J5: ='Raw Data'!J4 -> 44986 | ... L5: ='Raw Data'!L4 -> 45717 | N5: Median | O5: Mean
B6: Sales | C6: ='Raw Data'!C5 -> 32186 | D6: ='Raw Data'!D5 -> 33162 | E6: ='Raw Data'!E5 -> 35545 | F6: ='Raw Data'!F5 -> 39310 | G6: ='Raw Data'!G5 -> 39783 | H6: ='Raw Data'!H5 -> 47028 | I6: ='Raw Data'!I5 -> 52446 | J6: ='Raw Data'!J5 -> 60580 | ... L6: ='Raw Data'!L5 -> 63121
B7: EBIT | C7: ='Raw Data'!C14 -> 5557 | D7: ='Raw Data'!D14 -> 5896 | E7: ='Raw Data'!E14 -> 6979 | F7: ='Raw Data'!F14 -> 8315 | G7: ='Raw Data'!G14 -> 8859 | H7: ='Raw Data'!H14 -> 10552 | I7: ='Raw Data'!I14 -> 11766 | J7: ='Raw Data'!J14 -> 13010 | ... L7: ='Raw Data'!L14 -> 13488
B8: Actual Tax Payment | C8: ='Raw Data'!C23 -> 1875 | D8: ='Raw Data'!D23 -> 1977 | E8: ='Raw Data'!E23 -> 2079 | F8: ='Raw Data'!F23 -> 2544 | G8: ='Raw Data'!G23 -> 2409 | H8: ='Raw Data'!H23 -> 2606 | I8: ='Raw Data'!I23 -> 2987 | J8: ='Raw Data'!J23 -> 3201 | ... L8: ='Raw Data'!L23 -> 3744
B10: Tax % Sales | C10: =C8/C6 -> 0.058255142 | D10: =D8/D6 -> 0.059616428 | E10: =E8/E6 -> 0.058489239 | F10: =F8/F6 -> 0.064716357 | G10: =G8/G6 -> 0.060553503 | H10: =H8/H6 -> 0.055413796 | I10: =I8/I6 -> 0.056953819 | J10: =J8/J6 -> 0.052839221 | ... L10: =L8/L6 -> 0.05931465 | N10: =MEDIAN(C10:L10) -> 0.058681094 | O10: =AVERAGE(C10:L10) -> 0.05850251
B11: Tax % EBIT | C11: =C8/C7 -> 0.33741227 | D11: =D8/D7 -> 0.33531208 | E11: =E8/E7 -> 0.29789368 | F11: =F8/F7 -> 0.3059531 | G11: =G8/G7 -> 0.27192685 | H11: =H8/H7 -> 0.2469674 | I11: =I8/I7 -> 0.25386707 | J11: =J8/J7 -> 0.24604151 | ... L11: =L8/L7 -> 0.27758007 | N11: =MEDIAN(C11:L11) -> 0.27475346 | O11: =AVERAGE(C11:L11) -> 0.28440245
B13: Marginal Tax Rate | C13: =26%*(1+4%) -> 0.2704
B16: Forecasting Working Capital
B18: Particulars | C18: =C5 -> 42430 | D18: =D5 -> 42795 | E18: =E5 -> 43160 | F18: =F5 -> 43525 | G18: =G5 -> 43891 | H18: =H5 -> 44256 | I18: =I5 -> 44621 | J18: =J5 -> 44986 | ... L18: =L5 -> 45717
B19: Debtor Days | C19: ='Raw Data'!C106 -> 14 | D19: ='Raw Data'!D106 -> 12 | E19: ='Raw Data'!E106 -> 13 | F19: ='Raw Data'!F106 -> 17 | G19: ='Raw Data'!G106 -> 11 | H19: ='Raw Data'!H106 -> 14 | I19: ='Raw Data'!I106 -> 16 | J19: ='Raw Data'!J106 -> 19 | ... L19: ='Raw Data'!L106 -> 22 | N19: =MEDIAN(C19:L19) -> 15 | O19: =AVERAGE(C19:L19) -> 15.6
B20: Inventory Days | C20: ='Raw Data'!C107 -> 75 | D20: ='Raw Data'!D107 -> 67 | E20: ='Raw Data'!E107 -> 65 | F20: ='Raw Data'!F107 -> 59 | G20: ='Raw Data'!G107 -> 65 | H20: ='Raw Data'!H107 -> 66 | I20: ='Raw Data'!I107 -> 65 | J20: ='Raw Data'!J107 -> 55 | ... L20: ='Raw Data'!L107 -> 59 | N20: =MEDIAN(C20:L20) -> 65 | O20: =AVERAGE(C20:L20) -> 63.1
B21: Payble Days | C21: ='Raw Data'!C108 -> 156 | D21: ='Raw Data'!D108 -> 164 | E21: ='Raw Data'!E108 -> 185 | F21: ='Raw Data'!F108 -> 166 | G21: ='Raw Data'!G108 -> 176 | H21: ='Raw Data'!H108 -> 163 | I21: ='Raw Data'!I108 -> 145 | J21: ='Raw Data'!J108 -> 123 | ... L21: ='Raw Data'!L108 -> 152 | N21: =MEDIAN(C21:L21) -> 159.5 | O21: =AVERAGE(C21:L21) -> 157.3
B23: Debtors Day Analysis | C23: 2023 | D23: =C23+1 -> 2024 | E23: =D23+1 -> 2025 | F23: 2026 | G23: 2027 | H23: 2028 | I23: 2029 | J23: 2030
B24: Days Debtor Days | C24: =J19 -> 19 | D24: =K19 -> 18 | E24: =L19 -> 22 | F24: =15 -> 15 | G24: =15 -> 15 | H24: =15 -> 15 | I24: =15 -> 15 | J24: =15 -> 15
B25: Sales | C25: ='DCF Valuation'!C6 -> 60580 | D25: ='DCF Valuation'!D6 -> 61896 | E25: ='DCF Valuation'!E6 -> 63121 | F25: ='DCF Valuation'!F6 -> 66277.05 | G25: ='DCF Valuation'!G6 -> 69590.903 | H25: ='DCF Valuation'!H6 -> 73070.448 | I25: ='DCF Valuation'!I6 -> 76723.97 | J25: ='DCF Valuation'!J6 -> 80560.169
B26: Debtor Days in Year | C26: 365 | D26: 365 | E26: 365 | F26: 365 | G26: 365 | H26: 365 | I26: 365 | J26: 365
B28: Average Debtors | C28: =(C25/C26)*C24 -> 3153.4795 | D28: =(D25/D26)*D24 -> 3052.4055 | E28: =(E25/E26)*E24 -> 3804.5534 | F28: =(F25/F26)*F24 -> 2723.7144 | G28: =(G25/G26)*G24 -> 2859.9001 | H28: =(H25/H26)*H24 -> 3002.8951 | I28: =(I25/I26)*I24 -> 3153.0399 | J28: =(J25/J26)*J24 -> 3310.6919
B29: Average Debtors % Sales | C29: =C28/C25 -> 0.052054795 | D29: =D28/D25 -> 0.049315068 | E29: =E28/E25 -> 0.060273973 | F29: =F28/F25 -> 0.04109589 | G29: =G28/G25 -> 0.04109589 | H29: =H28/H25 -> 0.04109589 | I29: =I28/I25 -> 0.04109589 | J29: =J28/J25 -> 0.04109589
B31: Inventory Day Analysis
B32: Inventory Days | C32: =J20 -> 55 | D32: =K20 -> 55 | E32: =L20 -> 59 | F32: 64 | G32: 64 | H32: 64 | I32: 64 | J32: 64
B33: Sales | C33: ='DCF Valuation'!C6 -> 60580 | D33: ='DCF Valuation'!D6 -> 61896 | E33: ='DCF Valuation'!E6 -> 63121 | F33: ='DCF Valuation'!F6 -> 66277.05 | G33: ='DCF Valuation'!G6 -> 69590.903 | H33: ='DCF Valuation'!H6 -> 73070.448 | I33: ='DCF Valuation'!I6 -> 76723.97 | J33: ='DCF Valuation'!J6 -> 80560.169
B34: Inventory Days in Year | C34: 365 | D34: 365 | E34: 365 | F34: 365 | G34: 365 | H34: 365 | I34: 365 | J34: 365
B35: Average Debtors | C35: =(C33/C34)*C32 -> 9128.4932 | D35: =(D33/D34)*D32 -> 9326.7945 | E35: =(E33/E34)*E32 -> 10203.121 | F35: =(F33/F34)*F32 -> 11621.181 | G35: =(G33/G34)*G32 -> 12202.24 | H35: =(H33/H34)*H32 -> 12812.352 | I35: =(I33/I34)*I32 -> 13452.97 | J35: =(J33/J34)*J32 -> 14125.619
B36: Debtors % Sales | C36: =C35/C33 -> 0.15068493 | D36: =D35/D33 -> 0.15068493 | E36: =E35/E33 -> 0.16164384 | F36: =F35/F33 -> 0.17534247 | G36: =G35/G33 -> 0.17534247 | H36: =H35/H33 -> 0.17534247 | I36: =I35/I33 -> 0.17534247 | J36: =J35/J33 -> 0.17534247
B39: Payble Day Analysis
B40: Payble Days | C40: =J21 -> 123 | D40: =K21 -> 143 | E40: =L21 -> 152 | F40: 160 | G40: 160 | H40: 160 | I40: 160 | J40: 160
B41: Sales | C41: =C25 -> 60580 | D41: =D25 -> 61896 | E41: =E25 -> 63121 | F41: =F25 -> 66277.05 | G41: =G25 -> 69590.903 | H41: =H25 -> 73070.448 | I41: =I25 -> 76723.97 | J41: =J25 -> 80560.169
B42: Payble Days in Year | C42: 365 | D42: 365 | E42: 365 | F42: 365 | G42: 365 | H42: 365 | I42: 365 | J42: 365
B43: Average Payble | C43: =(C41/C42)*C40 -> 20414.63 | D43: =(D41/D42)*D40 -> 24249.666 | E43: =(E41/E42)*E40 -> 26286.005 | F43: =(F41/F42)*F40 -> 29052.953 | G43: =(G41/G42)*G40 -> 30505.601 | H43: =(H41/H42)*H40 -> 32030.881 | I43: =(I41/I42)*I40 -> 33632.425 | J43: =(J41/J42)*J40 -> 35314.046
B44: Payble % Sales | C44: =C43/C41 -> 0.3369863 | D44: =D43/D41 -> 0.39178082 | E44: =E43/E41 -> 0.41643836 | F44: =F43/F41 -> 0.43835616 | G44: =G43/G41 -> 0.43835616 | H44: =H43/H41 -> 0.43835616 | I44: =I43/I41 -> 0.43835616 | J44: =J43/J41 -> 0.43835616
B47: Average Debtors | C47: =C28 -> 3153.4795 | D47: =D28 -> 3052.4055 | E47: =E28 -> 3804.5534 | F47: =F28 -> 2723.7144 | G47: =G28 -> 2859.9001 | H47: =H28 -> 3002.8951 | I47: =I28 -> 3153.0399 | J47: =J28 -> 3310.6919
B48: Average Inventory | C48: =C35 -> 9128.4932 | D48: =D35 -> 9326.7945 | E48: =E35 -> 10203.121 | F48: =F35 -> 11621.181 | G48: =G35 -> 12202.24 | H48: =H35 -> 12812.352 | I48: =I35 -> 13452.97 | J48: =J35 -> 14125.619
B49: Average Payble | C49: =C43 -> 20414.63 | D49: =D43 -> 24249.666 | E49: =E43 -> 26286.005 | F49: =F43 -> 29052.953 | G49: =G43 -> 30505.601 | H49: =H43 -> 32030.881 | I49: =I43 -> 33632.425 | J49: =J43 -> 35314.046
B50: Working Capital | C50: =C47+C48-C49 -> -8132.6575 | D50: =D47+D48-D49 -> -11870.466 | E50: =E47+E48-E49 -> -12278.332 | F50: =F47+F48-F49 -> -14708.058 | G50: =G47+G48-G49 -> -15443.461 | H50: =H47+H48-H49 -> -16215.634 | I50: =I47+I48-I49 -> -17026.415 | J50: =J47+J48-J49 -> -17877.736
B53: Change in Working Capital | D53: =D50-C50 -> -3737.8082 | E53: =E50-D50 -> -407.86575 | F53: =F50-E50 -> -2429.7262 | G53: =G50-F50 -> -735.40288 | H53: =H50-G50 -> -772.17303 | I53: =I50-H50 -> -810.78168 | J53: =J50-I50 -> -851.32076
B55: Forecasting - Capex
B57: Particulars | C57: =C5 -> 42430 | D57: =D5 -> 42795 | E57: =E5 -> 43160 | F57: =F5 -> 43525 | G57: =G5 -> 43891 | H57: =H5 -> 44256 | I57: =I5 -> 44621 | J57: =J5 -> 44986 | ... L57: =L5 -> 45717
B58: Sales | C58: ='Raw Data'!C5 -> 32186 | D58: ='Raw Data'!D5 -> 33162 | E58: ='Raw Data'!E5 -> 35545 | F58: ='Raw Data'!F5 -> 39310 | G58: ='Raw Data'!G5 -> 39783 | H58: ='Raw Data'!H5 -> 47028 | I58: ='Raw Data'!I5 -> 52446 | J58: ='Raw Data'!J5 -> 60580 | ... L58: ='Raw Data'!L5 -> 63121
B59: Fixed assets purchased | C59: ='Raw Data'!C82 -> -810 | D59: ='Raw Data'!D82 -> -1113 | E59: ='Raw Data'!E82 -> -895 | F59: ='Raw Data'!F82 -> -767 | G59: ='Raw Data'!G82 -> -862 | H59: ='Raw Data'!H82 -> -4163 | I59: ='Raw Data'!I82 -> -1228 | J59: ='Raw Data'!J82 -> -1192 | ... L59: ='Raw Data'!L82 -> -1275
...

Sheet Sheet2
A1: COMPANY NAME | B1: HINDUSTAN UNILEVER LTD
A2: LATEST VERSION | B2: 2.1 | E2: PLEASE DO NOT MAKE ANY CHANGES TO THIS SHEET
A3: CURRENT VERSION | B3: 2.1
A5: META
A6: Number of shares
A7: Face Value | B7: 1
A8: Current Price | B8: 2544.9
A9: Market Capitalization | B9: 597947.48
A15: PROFIT & LOSS
A16: Report Date | B16: 42460 | C16: 42825 | D16: 43190 | E16: 43555 | F16: 43921 | G16: 44286 | H16: 44651 | I16: 45016 | J16: 45382 | K16: 45747
A17: Sales | B17: 32186 | C17: 33162 | D17: 35545 | E17: 39310 | F17: 39783 | G17: 47028 | H17: 52446 | I17: 60580 | J17: 61896 | K17: 63121
A18: Raw Material Cost | B18: 13184 | C18: 13606 | D18: 14233 | E18: 15845 | F18: 15697 | G18: 20141 | H18: 22871 | I18: 28427 | J18: 26822 | K18: 27344
A19: Change in Inventory | B19: -83 | C19: -144 | D19: 72 | E19: -12 | F19: 108 | G19: 405 | H19: 22 | I19: 75 | J19: 11 | K19: 153
A20: Power and Fuel | B20: 309 | C20: 295 | D20: 295 | E20: 308 | F20: 299 | G20: 339 | H20: 318 | I20: 384 | J20: 446 | K20: 427
A21: Other Mfr. Exp | B21: 2966 | C21: 2887 | D21: 2998 | E21: 3041 | F21: 2906 | G21: 2868 | H21: 3354 | I21: 3791 | J21: 3385 | K21: 3834
A22: Employee Cost | B22: 1680 | C22: 1743 | D22: 1860 | E22: 1875 | F22: 1820 | G22: 2358 | H22: 2545 | I22: 2854 | J22: 3009 | K22: 3077
A23: Selling and admin | B23: 6741 | C23: 6689 | D23: 7252 | E23: 7796 | F23: 7620 | G23: 7906 | H23: 8164 | I23: 8785 | J23: 10780 | K23: 10693
A24: Other Expenses | B24: 1313 | C24: 1470 | D24: 1480 | E24: 1553 | F24: 1688 | G24: 2195 | H24: 2359 | I24: 2267 | J24: 2806 | K24: 3056
A25: Other Income | B25: 486 | C25: 606 | D25: 353 | E25: 322 | F25: 424 | G25: 170 | H25: 219 | I25: 448 | J25: 817 | K25: 1322
A26: Depreciation | B26: 353 | C26: 432 | D26: 520 | E26: 565 | F26: 1002 | G26: 1074 | H26: 1091 | I26: 1137 | J26: 1216 | K26: 1355
A27: Interest | B27: 17 | C27: 35 | D27: 26 | E27: 33 | F27: 118 | G27: 117 | H27: 106 | I27: 114 | J27: 334 | K27: 395
... A31: Dividend Amount | B31: 3456 | C31: 3672 | D31: 4320 | E31: 4752 | F31: 5400 | G31: 9517.5 | H31: 7990 | I31: 9165 | J31: 9870 | K31: 12455
A32: Effective Tax Rate
A34: EBITDA
A40: Quarters
A41: Report Date | B41: 45016 | C41: 45107 | D41: 45199 | E41: 45291 | F41: 45382 | G41: 45473 | H41: 45565 | I41: 45657 | J41: 45747 | K41: 45838
A42: Sales | B42: 15215 | C42: 15496 | D42: 15623 | E42: 15567 | F42: 15210 | G42: 15707 | H42: 15926 | I42: 15818 | J42: 15670 | K42: 16514
A43: Expenses | B43: 11643 | C43: 11832 | D43: 11828 | E43: 11902 | F43: 11675 | G43: 11965 | H43: 12139 | I43: 12123 | J43: 12052 | K43: 12797
A44: Other Income | B44: 240 | C44: 146 | D44: 178 | E44: 184 | F44: 309 | G44: 209 | H44: 203 | I44: 740 | J44: 171 | K44: 74
A45: Depreciation | B45: 291 | C45: 286 | D45: 297 | E45: 313 | F45: 320 | G45: 329 | H45: 338 | I45: 341 | J45: 347 | K45: 361
A46: Interest | B46: 29 | C46: 50 | D46: 88 | E46: 91 | F46: 105 | G46: 93 | H46: 110 | I46: 112 | J46: 80 | K46: 127
A47: Profit before tax | B47: 3492 | C47: 3474 | D47: 3588 | E47: 3445 | F47: 3419 | G47: 3529 | H47: 3542 | I47: 3982 | J47: 3362 | K47: 3303
A48: Tax | B48: 891 | C48: 918 | D48: 931 | E48: 937 | F48: 858 | G48: 917 | H48: 947 | I48: 993 | J48: 887 | K48: 535
A49: Net profit | B49: 2600 | C49: 2554 | D49: 2656 | E49: 2509 | F49: 2558 | G49: 2610 | H49: 2591 | I49: 2984 | J49: 2464 | K49: 2756
A50: Operating Profit | B50: 3572 | C50: 3664 | D50: 3795 | E50: 3665 | F50: 3535 | G50: 3742 | H50: 3787 | I50: 3695 | J50: 3618 | K50: 3717
A51: EBITDA
A55: BALANCE SHEET
A56: Report Date | B56: 42460 | C56: 42825 | D56: 43190 | E56: 43555 | F56: 43921 | G56: 44286 | H56: 44651 | I56: 45016 | J56: 45382 | K56: 45747
A57: Equity Share Capital | B57: 216 | C57: 216 | D57: 216 | E57: 216 | F57: 216 | G57: 235 | H57: 235 | I57: 235 | J57: 235 | K57: 235
A58: Reserves | B58: 6357 | C58: 6528 | D58: 7065 | E58: 7651 | F58: 8013 | G58: 47439 | H58: 48826 | I58: 50069 | J58: 50983 | K58: 49167
...

Sheet Raw Data
C4: 42430 | D4: 42795 | E4: 43160 | F4: 43525 | G4: 43891 | H4: 44256 | I4: 44621 | J4: 44986 | K4: 45352 | L4: 45717
B5: Sales - | C5: 32186 | D5: 33162 | E5: 35545 | F5: 39310 | G5: 39783 | H5: 47028 | I5: 52446 | J5: 60580 | K5: 61896 | L5: 63121
B6: Sales Growth % | C6: 0.0067 | D6: 0.0303 | E6: 0.0719 | F6: 0.1059 | G6: 0.012 | H6: 0.1821 | I6: 0.1152 | J6: 0.1551 | K6: 0.0217 | L6: 0.0198
B7: Expenses - | C7: 26276 | D7: 26834 | E7: 28046 | F7: 30430 | G7: 29922 | H7: 35402 | I7: 39589 | J7: 46433 | K7: 47237 | L7: 48278
B8: Material Cost % + | C8: 0.4122 | D8: 0.4146 | E8: 0.3984 | F8: 0.4034 | G8: 0.3919 | H8: 0.4197 | I8: 0.4357 | J8: 0.468 | K8: 0.4332 | L8: 0.4308
B9: Manufacturing Cost % | C9: 0.1018 | D9: 0.096 | E9: 0.0926 | F9: 0.0852 | G9: 0.0806 | H9: 0.0682 | I9: 0.07 | J9: 0.0689 | K9: 0.0619 | L9: 0.0675
B10: Employee Cost % | C10: 0.0522 | D10: 0.0526 | E10: 0.0523 | F10: 0.0477 | G10: 0.0457 | H10: 0.0501 | I10: 0.0485 | J10: 0.0471 | K10: 0.0486 | L10: 0.0487
B11: Other Cost % | C11: 0.2502 | D11: 0.246 | E11: 0.2457 | F11: 0.2378 | G11: 0.234 | H11: 0.2148 | I11: 0.2006 | J11: 0.1824 | K11: 0.2195 | L11: 0.2178
B12: Operating Profit | C12: 5910 | D12: 6328 | E12: 7499 | F12: 8880 | G12: 9861 | H12: 11626 | I12: 12857 | J12: 14147 | K12: 14659 | L12: 14843
B13: OPM % | C13: 0.18 | D13: 0.19 | E13: 0.21 | F13: 0.23 | G13: 0.25 | H13: 0.25 | I13: 0.25 | J13: 0.23 | K13: 0.24 | L13: 0.24
B14: EBIT | C14: =C12-C20 -> 5557 | D14: =D12-D20 -> 5896 | E14: =E12-E20 -> 6979 | F14: =F12-F20 -> 8315 | G14: =G12-G20 -> 8859 | H14: =H12-H20 -> 10552 | I14: =I12-I20 -> 11766 | J14: =J12-J20 -> 13010 | ... L14: =L12-L20 -> 13488
B15: EBIT Margin | C15: =C14/C5 -> 0.17265271 | D15: =D14/D5 -> 0.17779386 | E15: =E14/E5 -> 0.19634266 | F15: =F14/F5 -> 0.21152379 | G15: =G14/G5 -> 0.22268306 | H15: =H14/H5 -> 0.22437697 | I15: =I14/I5 -> 0.22434504 | J15: =J14/J5 -> 0.21475735 | ... L15: =L14/L5 -> 0.21368483 | N15: =MEDIAN(C15:L15) -> 0.21422109 | O15: =AVERAGE(C15:L15) -> 0.20753471
B16: Other Income - | C16: 486 | D16: 606 | E16: 353 | F16: 322 | G16: 424 | H16: 170 | I16: 219 | J16: 448 | K16: 817 | L16: 1322
B17: Exceptional items | C17: -38 | D17: 246 | E17: -24 | F17: -224 | G17: -206 | H17: -240 | I17: -39 | J17: -64 | K17: 6 | L17: 305
B18: Other income normal | C18: 524 | D18: 360 | E18: 377 | F18: 546 | G18: 630 | H18: 410 | I18: 258 | J18: 512 | K18: 811 | L18: 1017
B19: Interest | C19: 17 | D19: 35 | E19: 26 | F19: 33 | G19: 118 | H19: 117 | I19: 106 | J19: 114 | K19: 334 | L19: 395
B20: Depreciation | C20: 353 | D20: 432 | E20: 520 | F20: 565 | G20: 1002 | H20: 1074 | I20: 1091 | J20: 1137 | K20: 1216 | L20: 1355 | N20: =MEDIAN(C20:L20) -> 1038 | O20: =AVERAGE(C20:L20) -> 874.5
B21: Derreciation % sales | C21: =C20/C5 -> 0.010967501 | D21: =D20/D5 -> 0.013026959 | E21: =E20/E5 -> 0.014629343 | F21: =F20/F5 -> 0.014372933 | G21: =G20/G5 -> 0.025186638 | H21: =H20/H5 -> 0.022837459 | I21: =I20/I5 -> 0.020802349 | J21: =J20/J5 -> 0.01876857 | ... L21: =L20/L5 -> 0.021466707 | N21: =MEDIAN(C21:L21) -> 0.019207214 | O21: =AVERAGE(C21:L21) -> 0.018170432
B22: Profit before tax | C22: 6026 | D22: 6467 | E22: 7306 | F22: 8604 | G22: 9165 | H22: 10605 | I22: 11879 | J22: 13344 | K22: 13926 | L22: 14415
B23: Actual Tax Payment | C23: =C22-C25 -> 1875 | D23: =D22-D25 -> 1977 | E23: =E22-E25 -> 2079 | F23: =F22-F25 -> 2544 | G23: =G22-G25 -> 2409 | H23: =H22-H25 -> 2606 | I23: =I22-I25 -> 2987 | J23: =J22-J25 -> 3201 | ... L23: =L22-L25 -> 3744
B24: Tax % | C24: 0.31 | D24: 0.31 | E24: 0.28 | F24: 0.3 | G24: 0.26 | H24: 0.25 | I24: 0.25 | J24: 0.24 | K24: 0.26 | L24: 0.26
B25: Net Profit + | C25: 4151 | D25: 4490 | E25: 5227 | F25: 6060 | G25: 6756 | H25: 7999 | I25: 8892 | J25: 10143 | K25: 10282 | L25: 10671
B26: EPS in Rs | C26: 19.18 | D26: 20.68 | E26: 24.09 | F26: 27.97 | G26: 31.17 | H26: 34.03 | I26: 37.79 | J26: 43.07 | K26: 43.74 | L26: 45.32
B27: Dividend Payout % | C27: 0.83 | D27: 0.82 | E27: 0.83 | F27: 0.78 | G27: 0.8 | H27: 1.19 | I27: 0.9 | J27: 0.91 | K27: 0.96 | L27: 1.17
N28: Upper 95.0%
B29: Balance sheet | N29: -5518833.6
C30: 42430 | D30: 42795 | E30: 43160 | F30: 43525 | G30: 43891 | H30: 44256 | I30: 44621 | J30: 44986 | K30: 45352 | L30: 45717 | N30: 0
B31: Equity Capital | C31: 216 | D31: 216 | E31: 216 | F31: 216 | G31: 216 | H31: 235 | I31: 235 | J31: 235 | K31: 235 | L31: 235 | N31: 4043.9235
B32: Reserves | C32: 6357 | D32: 6528 | E32: 7065 | F32: 7651 | G32: 8013 | H32: 47439 | I32: 48826 | J32: 50069 | K32: 50983 | L32: 49167
B33: Borrowings - | C33: 177 | D33: 277 | E33: 0 | F33: 99 | G33: 0 | H33: 0 | I33: 1043 | J33: 1219 | K33: 1484 | L33: 1648
B34: Long term Borrowings | C34: 0 | D34: 0 | E34: 0 | F34: 0 | G34: 0 | H34: 0 | I34: 0 | J34: 0 | K34: 0 | L34: 0
B35: Short term Borrowings | C35: 177 | D35: 277 | E35: 0 | F35: 99 | G35: 0 | H35: 0 | I35: 0 | J35: 98 | K35: 13 | L35: 1
B36: Lease Liabilities | C36: 0 | D36: 0 | E36: 0 | F36: 0 | G36: 0 | H36: 0 | I36: 1043 | J36: 1121 | K36: 1471 | L36: 1647
B37: Other Liabilities - | C37: 8043 | D37: 8685 | E37: 10581 | F37: 10663 | G37: 11924 | H37: 21066 | I37: 20402 | J37: 21554 | K37: 25787 | L37: 28813
B38: Non controlling int | C38: 20 | D38: 22 | E38: 20 | F38: 18 | G38: 17 | H38: 20 | I38: 26 | J38: 218 | K38: 205 | L38: 207
B39: Trade Payables | C39: 5685 | D39: 6186 | E39: 7170 | F39: 7206 | G39: 7535 | H39: 8802 | I39: 9068 | J39: 9574 | K39: 10486 | L39: 11315
B40: Advance from Customers | C40: 45 | D40: 78 | E40: 62 | F40: 43 | G40: 158 | H40: 96 | I40: 119 | J40: 98 | K40: 91 | L40: 105
B41: Other liability items | C41: 2293 | D41: 2399 | E41: 3329 | F41: 3396 | G41: 4214 | H41: 12148 | I41: 11189 | J41: 11664 | K41: 15005 | L41: 17186
B42: Total Liabilities | C42: 14793 | D42: 15706 | E42: 17862 | F42: 18629 | G42: 20153 | H42: 68740 | I42: 70506 | J42: 73077 | K42: 78489 | L42: 79863
B43: Fixed Assets - | C43: 3258 | D43: 4419 | E43: 4528 | F43: 4715 | G43: 5479 | H43: 51443 | I43: 51473 | J43: 52678 | K43: 53744 | L43: 54335
...
